sample_io/out.txt
orders read: 10, symbols: AAPL,MSFT

--- responses ---
EngineOrderResponse [status:ACCEPTED client:1 symbol:AAPL coid:1001 moid:1001 side:BUY exec:0 leaves:50 price:190]
EngineOrderResponse [status:ACCEPTED client:2 symbol:AAPL coid:1002 moid:1002 side:BUY exec:0 leaves:20 price:191]
EngineOrderResponse [status:ACCEPTED client:3 symbol:AAPL coid:1003 moid:1003 side:SELL exec:0 leaves:30 price:190]
EngineOrderResponse [status:FILLED client:3 symbol:AAPL coid:1003 moid:1003 side:SELL exec:20 leaves:10 price:191]
EngineOrderResponse [status:FILLED client:2 symbol:AAPL coid:1002 moid:1002 side:BUY exec:20 leaves:0 price:191]
EngineOrderResponse [status:FILLED client:3 symbol:AAPL coid:1003 moid:1003 side:SELL exec:10 leaves:0 price:190]
EngineOrderResponse [status:FILLED client:1 symbol:AAPL coid:1001 moid:1001 side:BUY exec:10 leaves:40 price:190]
EngineOrderResponse [status:ACCEPTED client:4 symbol:AAPL coid:1004 moid:1004 side:SELL exec:0 leaves:100 price:-9223372036854775808]
EngineOrderResponse [status:FILLED client:4 symbol:AAPL coid:1004 moid:1004 side:SELL exec:40 leaves:60 price:190]
EngineOrderResponse [status:FILLED client:1 symbol:AAPL coid:1001 moid:1001 side:BUY exec:40 leaves:0 price:190]
EngineOrderResponse [status:CANCELED client:4 symbol:AAPL coid:1004 moid:1004 side:SELL exec:40 leaves:60 price:-9223372036854775808]
EngineOrderResponse [status:CANCEL_REJECTED client:1 symbol:AAPL coid:1001 moid:18446744073709551615 side:INVALID exec:18446744073709551615 leaves:18446744073709551615 price:-9223372036854775808]
EngineOrderResponse [status:CANCEL_REJECTED client:9 symbol:AAPL coid:9999 moid:18446744073709551615 side:INVALID exec:18446744073709551615 leaves:18446744073709551615 price:-9223372036854775808]
EngineOrderResponse [status:ACCEPTED client:5 symbol:MSFT coid:2001 moid:2001 side:BUY exec:0 leaves:10 price:300]
EngineOrderResponse [status:ACCEPTED client:6 symbol:MSFT coid:2002 moid:2002 side:SELL exec:0 leaves:5 price:299]
EngineOrderResponse [status:FILLED client:6 symbol:MSFT coid:2002 moid:2002 side:SELL exec:5 leaves:0 price:300]
EngineOrderResponse [status:FILLED client:5 symbol:MSFT coid:2001 moid:2001 side:BUY exec:5 leaves:5 price:300]
EngineOrderResponse [status:MODIFIED client:5 symbol:MSFT coid:2001 moid:2001 side:BUY exec:0 leaves:20 price:300]
EngineOrderResponse [status:ACCEPTED client:7 symbol:MSFT coid:2003 moid:2003 side:SELL exec:0 leaves:15 price:301]
EngineOrderResponse [status:CANCELED client:7 symbol:MSFT coid:2003 moid:2003 side:SELL exec:0 leaves:15 price:301]

--- book updates ---
BookUpdate [type:ADD oid:1001 symbol:AAPL side:BUY qty:50 price:190]
BookUpdate [type:ADD oid:1002 symbol:AAPL side:BUY qty:20 price:191]
BookUpdate [type:TRADE oid:1002 symbol:AAPL side:BUY qty:20 price:191]
BookUpdate [type:TRADE oid:1001 symbol:AAPL side:BUY qty:10 price:190]
BookUpdate [type:MODIFY oid:1001 symbol:AAPL side:BUY qty:40 price:190]
BookUpdate [type:TRADE oid:1001 symbol:AAPL side:BUY qty:40 price:190]
BookUpdate [type:ADD oid:2001 symbol:MSFT side:BUY qty:10 price:300]
BookUpdate [type:TRADE oid:2001 symbol:MSFT side:BUY qty:5 price:300]
BookUpdate [type:MODIFY oid:2001 symbol:MSFT side:BUY qty:5 price:300]
BookUpdate [type:MODIFY oid:2001 symbol:MSFT side:BUY qty:20 price:300]
