sample_io/exchange_order_gateway.log
2026-08-16 17:41:27 [INFO] [/workspaces/TradingMatchingEngine/exchange/order_server/order_server.h:69 run] OrderGatewayServer run loop starting
2026-08-16 17:41:30 [INFO] [/workspaces/TradingMatchingEngine/exchange/order_server/request_sequencer.h:61 flush] sequencing EngineOrderRequest [type:LIMIT client:1 symbol:AAPL oid:1001 side:BUY qty:50 price:190 rx:1786902090598292107]
2026-08-16 17:41:30 [INFO] [/workspaces/TradingMatchingEngine/exchange/order_server/request_sequencer.h:61 flush] sequencing EngineOrderRequest [type:LIMIT client:2 symbol:AAPL oid:1002 side:BUY qty:20 price:191 rx:1786902090598293479]
2026-08-16 17:41:30 [INFO] [/workspaces/TradingMatchingEngine/exchange/order_server/request_sequencer.h:61 flush] sequencing EngineOrderRequest [type:LIMIT client:3 symbol:AAPL oid:1003 side:SELL qty:30 price:190 rx:1786902090598293790]
2026-08-16 17:41:30 [INFO] [/workspaces/TradingMatchingEngine/exchange/order_server/request_sequencer.h:61 flush] sequencing EngineOrderRequest [type:MARKET client:4 symbol:AAPL oid:1004 side:SELL qty:100 price:0 rx:1786902090598299260]
2026-08-16 17:41:30 [INFO] [/workspaces/TradingMatchingEngine/exchange/order_server/request_sequencer.h:61 flush] sequencing EngineOrderRequest [type:LIMIT client:5 symbol:MSFT oid:2001 side:BUY qty:10 price:300 rx:1786902090598299340]
2026-08-16 17:41:30 [INFO] [/workspaces/TradingMatchingEngine/exchange/order_server/request_sequencer.h:61 flush] sequencing EngineOrderRequest [type:LIMIT client:6 symbol:MSFT oid:2002 side:SELL qty:5 price:299 rx:1786902090598299651]
2026-08-16 17:41:30 [INFO] [/workspaces/TradingMatchingEngine/exchange/order_server/request_sequencer.h:61 flush] sequencing EngineOrderRequest [type:CANCEL client:1 symbol:AAPL oid:1001 side:INVALID qty:0 price:0 rx:1786902090598299721]
2026-08-16 17:41:30 [INFO] [/workspaces/TradingMatchingEngine/exchange/order_server/request_sequencer.h:61 flush] sequencing EngineOrderRequest [type:MODIFY client:5 symbol:MSFT oid:2001 side:INVALID qty:20 price:300 rx:1786902090598299781]
2026-08-16 17:41:30 [INFO] [/workspaces/TradingMatchingEngine/exchange/order_server/request_sequencer.h:61 flush] sequencing EngineOrderRequest [type:IOC client:7 symbol:MSFT oid:2003 side:SELL qty:15 price:301 rx:1786902090598299841]
2026-08-16 17:41:30 [INFO] [/workspaces/TradingMatchingEngine/exchange/order_server/request_sequencer.h:61 flush] sequencing EngineOrderRequest [type:CANCEL client:9 symbol:AAPL oid:9999 side:INVALID qty:0 price:0 rx:1786902090598300172]
2026-08-16 17:41:30 [INFO] [/workspaces/TradingMatchingEngine/exchange/order_server/order_server.h:115 drainResponses] response EngineOrderResponse [status:ACCEPTED client:1 symbol:AAPL coid:1001 moid:1001 side:BUY exec:0 leaves:50 price:190]
2026-08-16 17:41:30 [INFO] [/workspaces/TradingMatchingEngine/exchange/order_server/order_server.h:115 drainResponses] response EngineOrderResponse [status:ACCEPTED client:2 symbol:AAPL coid:1002 moid:1002 side:BUY exec:0 leaves:20 price:191]
2026-08-16 17:41:30 [INFO] [/workspaces/TradingMatchingEngine/exchange/order_server/order_server.h:115 drainResponses] response EngineOrderResponse [status:ACCEPTED client:3 symbol:AAPL coid:1003 moid:1003 side:SELL exec:0 leaves:30 price:190]
2026-08-16 17:41:30 [INFO] [/workspaces/TradingMatchingEngine/exchange/order_server/order_server.h:115 drainResponses] response EngineOrderResponse [status:FILLED client:3 symbol:AAPL coid:1003 moid:1003 side:SELL exec:20 leaves:10 price:191]
2026-08-16 17:41:30 [INFO] [/workspaces/TradingMatchingEngine/exchange/order_server/order_server.h:115 drainResponses] response EngineOrderResponse [status:FILLED client:2 symbol:AAPL coid:1002 moid:1002 side:BUY exec:20 leaves:0 price:191]
2026-08-16 17:41:30 [INFO] [/workspaces/TradingMatchingEngine/exchange/order_server/order_server.h:115 drainResponses] response EngineOrderResponse [status:FILLED client:3 symbol:AAPL coid:1003 moid:1003 side:SELL exec:10 leaves:0 price:190]
2026-08-16 17:41:30 [INFO] [/workspaces/TradingMatchingEngine/exchange/order_server/order_server.h:115 drainResponses] response EngineOrderResponse [status:FILLED client:1 symbol:AAPL coid:1001 moid:1001 side:BUY exec:10 leaves:40 price:190]
2026-08-16 17:41:30 [INFO] [/workspaces/TradingMatchingEngine/exchange/order_server/order_server.h:115 drainResponses] response EngineOrderResponse [status:ACCEPTED client:4 symbol:AAPL coid:1004 moid:1004 side:SELL exec:0 leaves:100 price:-922337203685472026-08-16 17:41:30 [INFO] [/workspaces/TradingMatchingEngine/exchange/order_server/order_server.h:115 drainResponses] response EngineOrderResponse [status:FILLED client:4 symbol:AAPL coid:1004 moid:1004 side:SELL exec:40 leaves:60 price:190]
2026-08-16 17:41:30 [INFO] [/workspaces/TradingMatchingEngine/exchange/order_server/order_server.h:115 drainResponses] response EngineOrderResponse [status:FILLED client:1 symbol:AAPL coid:1001 moid:1001 side:BUY exec:40 leaves:0 price:190]
2026-08-16 17:41:30 [INFO] [/workspaces/TradingMatchingEngine/exchange/order_server/order_server.h:115 drainResponses] response EngineOrderResponse [status:CANCELED client:4 symbol:AAPL coid:1004 moid:1004 side:SELL exec:40 leaves:60 price:-922337203685472026-08-16 17:41:30 [INFO] [/workspaces/TradingMatchingEngine/exchange/order_server/order_server.h:115 drainResponses] response EngineOrderResponse [status:CANCEL_REJECTED client:1 symbol:AAPL coid:1001 moid:18446744073709551615 side:INVALID exec:184467442026-08-16 17:41:30 [INFO] [/workspaces/TradingMatchingEngine/exchange/order_server/order_server.h:115 drainResponses] response EngineOrderResponse [status:CANCEL_REJECTED client:9 symbol:AAPL coid:9999 moid:18446744073709551615 side:INVALID exec:184467442026-08-16 17:41:30 [INFO] [/workspaces/TradingMatchingEngine/exchange/order_server/order_server.h:115 drainResponses] response EngineOrderResponse [status:ACCEPTED client:5 symbol:MSFT coid:2001 moid:2001 side:BUY exec:0 leaves:10 price:300]
2026-08-16 17:41:30 [INFO] [/workspaces/TradingMatchingEngine/exchange/order_server/order_server.h:115 drainResponses] response EngineOrderResponse [status:ACCEPTED client:6 symbol:MSFT coid:2002 moid:2002 side:SELL exec:0 leaves:5 price:299]
2026-08-16 17:41:30 [INFO] [/workspaces/TradingMatchingEngine/exchange/order_server/order_server.h:115 drainResponses] response EngineOrderResponse [status:FILLED client:6 symbol:MSFT coid:2002 moid:2002 side:SELL exec:5 leaves:0 price:300]
2026-08-16 17:41:30 [INFO] [/workspaces/TradingMatchingEngine/exchange/order_server/order_server.h:115 drainResponses] response EngineOrderResponse [status:FILLED client:5 symbol:MSFT coid:2001 moid:2001 side:BUY exec:5 leaves:5 price:300]
2026-08-16 17:41:30 [INFO] [/workspaces/TradingMatchingEngine/exchange/order_server/order_server.h:115 drainResponses] response EngineOrderResponse [status:MODIFIED client:5 symbol:MSFT coid:2001 moid:2001 side:BUY exec:0 leaves:20 price:300]
2026-08-16 17:41:30 [INFO] [/workspaces/TradingMatchingEngine/exchange/order_server/order_server.h:115 drainResponses] response EngineOrderResponse [status:ACCEPTED client:7 symbol:MSFT coid:2003 moid:2003 side:SELL exec:0 leaves:15 price:301]
2026-08-16 17:41:30 [INFO] [/workspaces/TradingMatchingEngine/exchange/order_server/order_server.h:115 drainResponses] response EngineOrderResponse [status:CANCELED client:7 symbol:MSFT coid:2003 moid:2003 side:SELL exec:0 leaves:15 price:301]
