sample_io/sample_orders.txt
# sample order flow across two symbols, exercising every order type
# format: TYPE,client_id,symbol,order_id,side,price,qty
LIMIT,1,AAPL,1001,BUY,190,50
LIMIT,2,AAPL,1002,BUY,191,20
LIMIT,3,AAPL,1003,SELL,190,30
MARKET,4,AAPL,1004,SELL,0,100
LIMIT,5,MSFT,2001,BUY,300,10
LIMIT,6,MSFT,2002,SELL,299,5
CANCEL,1,AAPL,1001,-,0,0
MODIFY,5,MSFT,2001,-,300,20
IOC,7,MSFT,2003,SELL,301,15
CANCEL,9,AAPL,9999,-,0,0
